"use server";

import * as z from "zod";
import { LoginSchema } from "@/schemas";
import { signIn } from "@/auth";
import { DEFAULT_LOGIN_REDIRECT } from "@/routes";
import { AuthError } from "next-auth";
import { generateVerificationToken } from "@/lib/tokens";
import { getUserByEmail } from "@/data/user";
import { sendVerificationEmail } from "@/lib/sendEmail";

export const login = async (values: z.infer<typeof LoginSchema>) => {
  const validatedFields = LoginSchema.safeParse(values);

  if (!validatedFields.success) {
    return { error: "Invalid fields!" };
  }

  const { email, password } = validatedFields.data;

  const existingUser = await getUserByEmail(email);

  if (!existingUser || !existingUser.email || !existingUser.password) {
    return { error: "Email does not exist or is in use!" };
  }

  if (!existingUser.emailVerified) {
    const verificationToken = await generateVerificationToken(
      existingUser.email
    );

    try {
      await sendVerificationEmail(
        verificationToken.email,
        verificationToken.token
      );
      return {
        success:
          "Your email is not verified yet, confirmation email sent again. check your inbox or spam!",
      };
    } catch (error) {
      console.error("Error sending confirmation email:", error);
      return { error: "Error sending confirmation email; Try again later!" };
    }
  }

  try {
    await signIn("credentials", {
      email,
      password,
      redirectTo: DEFAULT_LOGIN_REDIRECT,
    });
  } catch (error) {
    if (error instanceof AuthError) {
      switch (error.type) {
        case "CredentialsSignin":
          return { error: "Invalid credential!" };
        // TODO(FIX): For some reason this Invalid credentials! error is not rendered even if the credentiols are wrong, it will throw the next error!
        default:
          return { error: "Something went wrong!" };
      }
    }
    throw error;
  }
};
